Workbook
Name CASE: #REF!
Name CIRC: #REF!

Sheet Main LBO
B2: LBO
A4: x | B4: IRR | R4: Mo-Bruk Estimates
K5: IRR (for reference) | L5: =L186 -> 0.302755 | O5: Scenario Choosen: | Q5: Base case | R5: ▼
B7: Assumptions | Q7: 2025E | R7: 2026E | S7: 2027E | T7: 2028E | U7: 2029E
B9: Transaction Background | I9: Valuation at Entry | O9: Revenue growth | Q9: =INDEX(Q14:Q16, MATCH($Q$5, {"Base case";"Bull case";"Bear case"}, 0)) -> 0.221 | R9: =INDEX(R14:R16, MATCH($Q$5, {"Base case";"Bull case";"Bear case"}, 0)) -> 0.118 | S9: =INDEX(S14:S16, MATCH($Q$5, {"Base case";"Bull case";"Bear case"}, 0)) -> 0.111 | T9: =INDEX(T14:T16, MATCH($Q$5, {"Base case";"Bull case";"Bear case"}, 0)) -> 0.104 | U9: =INDEX(U14:U16, MATCH($Q$5, {"Base case";"Bull case";"Bear case"}, 0)) -> 0.105
B10: Company name | E10: Mo-Bruk | I10: Offer value / share | L10: =E11*(1+L11) -> 404.5815 | O10: Gross margin | Q10: =INDEX(Q19:Q21, MATCH($Q$5, {"Base case";"Bull case";"Bear case"}, 0)) -> 0.469 | R10: =INDEX(R19:R21, MATCH($Q$5, {"Base case";"Bull case";"Bear case"}, 0)) -> 0.485 | S10: =INDEX(S19:S21, MATCH($Q$5, {"Base case";"Bull case";"Bear case"}, 0)) -> 0.487 | T10: =INDEX(T19:T21, MATCH($Q$5, {"Base case";"Bull case";"Bear case"}, 0)) -> 0.487 | U10: =INDEX(U19:U21, MATCH($Q$5, {"Base case";"Bull case";"Bear case"}, 0)) -> 0.487
B11: Latest closing share price | E11: 310.5 | I11: % Premium / discount | L11: 0.303 | O11: OpEx margin | Q11: =INDEX(Q24:Q26, MATCH($Q$5, {"Base case";"Bull case";"Bear case"}, 0)) -> 0.071535429 | R11: =INDEX(R24:R26, MATCH($Q$5, {"Base case";"Bull case";"Bear case"}, 0)) -> 0.071535429 | S11: =INDEX(S24:S26, MATCH($Q$5, {"Base case";"Bull case";"Bear case"}, 0)) -> 0.071535429 | T11: =INDEX(T24:T26, MATCH($Q$5, {"Base case";"Bull case";"Bear case"}, 0)) -> 0.071535429 | U11: =INDEX(U24:U26, MATCH($Q$5, {"Base case";"Bull case";"Bear case"}, 0)) -> 0.071535429
B12: Latest closing share price date | E12: 45384
B13: Current EBITDA multiple | E13: =((E11*L14)-L16+L17)/L20 -> 7.954569 | I13: Offer value (Equity value) | L13: =L10*L14 -> 1421.2483 | N13: INPUT SHEET | O13: Revenue growth | Q13: 2025E | R13: 2026E | S13: 2027E | T13: 2028E | U13: 2029E
B14: Market cap | E14: =E11*L14 -> 1090.7508 | I14: Shares outstanding (m) | L14: =3512885/1000000 -> 3.512885 | O14: Base case | Q14: 0.221 | R14: 0.118 | S14: 0.111 | T14: 0.104 | U14: 0.105
O15: Bull case | Q15: =Q14+0.02 -> 0.241 | R15: =R14+0.02 -> 0.138 | S15: =S14+0.02 -> 0.131 | T15: =T14+0.02 -> 0.124 | U15: =U14+0.02 -> 0.125
B16: Transaction Financials and Assumptions | I16: Debt | L16: =E18 -> 142.311 | O16: Bear case | Q16: =Q14-0.02 -> 0.201 | R16: =R14-0.02 -> 0.098 | S16: =S14-0.02 -> 0.091 | T16: =T14-0.02 -> 0.084 | U16: =U14-0.02 -> 0.085
B17: EBITDA | E17: ='Financials Data'!L7 -> 126.13 | I17: Cash | L17: =E19 -> 54.87
B18: Debt | E18: =142.311 -> 142.311 | O18: Gross margin | Q18: 2025E | R18: 2026E | S18: 2027E | T18: 2028E | U18: 2029E
B19: Cash | E19: ='Financials Data'!AF6 -> 54.87 | F19: #Assuming this cash is contained | I19: Enterprise Value | L19: =L13+L16-L17 -> 1508.6893 | O19: Base case: | Q19: 0.469 | R19: 0.485 | S19: 0.487 | T19: 0.487 | U19: 0.487
B20: Exit Multiple | E20: =L21 -> 11.961383 | I20: LTM EBITDA | L20: =E17 -> 126.13 | O20: Bull case: | Q20: =Q19+0.02 -> 0.489 | R20: =R19+0.02 -> 0.505 | S20: =S19+0.02 -> 0.507 | T20: =T19+0.02 -> 0.507 | U20: =U19+0.02 -> 0.507
I21: Entry Multiple | L21: =L19/L20 -> 11.961383 | O21: Bear case | Q21: =Q19-0.02 -> 0.449 | R21: =R19-0.02 -> 0.465 | S21: =S19-0.02 -> 0.467 | T21: =T19-0.02 -> 0.467 | U21: =U19-0.02 -> 0.467
B23: Capital Structure | O23: OpEx margin | Q23: 2025E | R23: 2026E | S23: 2027E | T23: 2028E | U23: 2029E
E24: Amount | F24: xEBITDA | G24: Interest (%) | H24: Ink. 3y. interest swap | I24: Total debt (%) | J24: Spread ex. swap 10y | K24: Term | O24: Base case: | Q24: 0.071535429 | R24: 0.071535429 | S24: 0.071535429 | T24: 0.071535429 | U24: 0.071535429
B25: Revolver | E25: 0 | F25: =E25/$E$17 -> 0 | G25: 0.088 | I25: 0 | J25: =(G25-' WACC & Unlevered CoC'!$D$5)*10000 -> 295.5 | K25: 6 | O25: Bull case: | Q25: =Q24-0.02 -> 0.051535429 | R25: =R24-0.02 -> 0.051535429 | S25: =S24-0.02 -> 0.051535429 | T25: =T24-0.02 -> 0.051535429 | U25: =U24-0.02 -> 0.051535429
B26: Senior debt - PLN Term loan A | E26: 540 | F26: =E26/$E$17 -> 4.2812971 | G26: 0.0781 | H26: =G26+0.002 -> 0.0801 | I26: =E26/$E$30 -> 0.6 | J26: =(G26-' WACC & Unlevered CoC'!$D$5)*10000 -> 196.5 | K26: 6 | O26: Bear case | Q26: =Q24+0.02 -> 0.091535429 | R26: =R24+0.02 -> 0.091535429 | S26: =S24+0.02 -> 0.091535429 | T26: =T24+0.02 -> 0.091535429 | U26: =U24+0.02 -> 0.091535429
B27: Senior debt - PLN Term loan B | E27: 140 | F27: =E27/$E$17 -> 1.1099659 | G27: 0.0794 | I27: =E27/$E$30 -> 0.15555556 | J27: =(G27-' WACC & Unlevered CoC'!$D$5)*10000 -> 209.5 | K27: 5
B28: Subordinate debt - PLN Second Lien | E28: 220 | F28: =E28/$E$17 -> 1.7442321 | G28: 0.1031 | I28: =E28/$E$30 -> 0.24444444 | J28: =(G28-' WACC & Unlevered CoC'!$D$5)*10000 -> 446.5 | K28: 6
B30: Total | E30: =SUM(E25:E28) -> 900 | F30: =SUM(F25:F28) -> 7.1354951 | G30: =(I26*G26)+(I27*G27)+(I28*G28)+(G25*I25) -> 0.084413333 | I30: =SUM(I25:I28) -> 1
A32: x | B32: Sources and Uses
B34: Sources | I34: Uses
D35: Amount | E35: xEBITDA | F35: % Capital | J35: Amount | K35: xEBITDA | L35: % Capital
B36: =B25 -> Revolver | D36: 0 | E36: 0 | F36: 0 | I36: Equity payment | J36: =L13 -> 1421.2483 | K36: =J36/$E$17 -> 11.268122 | L36: =J36/$J$43 -> 0.89286924
B37: =B26 -> Senior debt - PLN Term loan A | D37: =E26 -> 540 | E37: =D37/$E$17 -> 4.2812971 | F37: =D37/$D$43 -> 0.3392436 | I37: Debt refinancing | J37: =E18-27.5 -> 114.811 | K37: =J37/$E$17 -> 0.91025926 | L37: =J37/$J$43 -> 0.072127588
B38: =B27 -> Senior debt - PLN Term loan B | D38: =E27 -> 140 | E38: =D38/$E$17 -> 1.1099659 | F38: =D38/$D$43 -> 0.087952045 | I38: Transaction fee | J38: =L19*0.025 -> 37.717232 | K38: =J38/$E$17 -> 0.29903458 | L38: =J38/$J$43 -> 0.023695055
B39: =B28 -> Subordinate debt - PLN Second Lien | D39: =E28 -> 220 | E39: =D39/$E$17 -> 1.7442321 | F39: =D39/$D$43 -> 0.13821036 | I39: Financing fees | J39: =E30*0.02 -> 18 | K39: =J39/$E$17 -> 0.1427099 | L39: =J39/$J$43 -> 0.01130812 | N39: Assuming 2,5% of the equity offer
B40: Cash on hand | D40: =E19 -> 54.87 | E40: =D40/$E$17 -> 0.43502735 | F40: =D40/$D$43 -> 0.034470919 | N40: Assuming 2% of the total debt
B41: Sponsor equity | D41: =D43-SUM(D37:D40) -> 636.90651 | E41: =D41/$E$17 -> 5.0496037 | F41: =D41/$D$43 -> 0.40012308
B43: Total | D43: =J43 -> 1591.7765 | E43: =SUM(E37:E41) -> 12.620126 | F43: =D43/$D$43 -> 1 | I43: Total | J43: =SUM(J36:J41) -> 1591.7765 | K43: =SUM(K36:K41) -> 12.620126 | L43: =SUM(L36:L41) -> 1
A45: x | B45: Financials (Lastest report Q3-2024)
B47: Assumptions (blue) | D47: 2021 | E47: 2022 | F47: 2023 | G47: 2024(E) | H47: 2025E | I47: 2026E | J47: 2027E | K47: 2028E | L47: 2029E | O47: Averages
B49: Revenue growth | E49: =E62/D62-1 -> -0.08914337 | F49: =F62/E62-1 -> -0.026213074 | G49: =G62/F62-1 -> 0.2151386 | H49: =Q9 -> 0.221 | I49: =R9 -> 0.118 | J49: =S9 -> 0.111 | K49: =T9 -> 0.104 | L49: =U9 -> 0.105 | N49: =Q5 -> Base case | O49: =AVERAGE(H49:L49) -> 0.1318
B50: Gross margin | D50: =D68/D$62 -> 0.61820291 | E50: =E68/E$62 -> 0.50860758 | F50: =F68/F$62 -> 0.47884056 | G50: =G68/G$62 -> 0.48732639 | H50: =Q10 -> 0.469 | I50: =R10 -> 0.485 | J50: =S10 -> 0.487 | K50: =T10 -> 0.487 | L50: =U10 -> 0.487 | O50: =AVERAGE(H50:L50) -> 0.483
B51: OpEx margin | D51: =D71/D$62 -> 0.071816175 | E51: =E71/E$62 -> 0.050084227 | F51: =F71/F$62 -> 0.074553816 | G51: =G71/G$62 -> 0.0896875 | H51: =Q11 -> 0.071535429 | I51: =R11 -> 0.071535429 | J51: =S11 -> 0.071535429 | K51: =T11 -> 0.071535429 | L51: =U11 -> 0.071535429 | O51: =AVERAGE(H51:L51) -> 0.071535429
B52: Tax rate | D52: =D83/D80 -> 0.19432079 | E52: =E83/E80 -> 0.18930257 | F52: =F83/F80 -> 0.18625696 | G52: =F52-$N$52 -> 0.18625696 | H52: 0.19 | I52: 0.19 | J52: 0.19 | K52: 0.19 | L52: 0.19 | O52: =AVERAGE(H52:L52) -> 0.19
...

Sheet Financials Data
B3: Income Statement | TIKR.com | C3: 43465 | D3: 43830 | E3: 44196 | F3: 44561 | G3: 44926 | H3: 45291 | I3: LTM | K3: Actuals & Forward Estimates | TIKR.com | L3: 31/12/24 E | M3: 31/12/25 E | N3: 31/12/26 E | O3: 31/12/27 E | P3: 31/12/28 E | Q3: CAGR | S3: Cash Flow Statement | TIKR.com | T3: 43465 | U3: 43830 | V3: 44196 | W3: 44561 | X3: 44926 | Y3: 45291 | AA3: Balance Sheet | TIKR.com | AB3: 44196 | AC3: 44561 | AD3: 44926 | AE3: 45291 | AF3: LTM
AA4: Cash And Equivalents | AB4: 49.34 | AC4: 114.13 | AD4: 86.79 | AE4: 18.16 | AF4: 54.87
B5: Revenues | C5: 92.67 | D5: 130.57 | E5: 178.46 | F5: 267.21 | G5: 243.39 | H5: 237.01 | I5: 267.62 | K5: Revenue | L5: 288 | M5: 331.6 | N5: 379.15 | O5: 394.9 | P5: 408 | Q5: 0.091 | S5: Net Income | T5: 20.52 | U5: 40.09 | V5: 78.73 | W5: 114.99 | X5: 92.15 | Y5: 78.86 | AA5: Short Term Investments | AB5: 5
B6: Total Revenues | C6: 92.67 | D6: 130.57 | E6: 178.46 | F6: 267.21 | G6: 243.39 | H6: 237.01 | I6: 267.62 | K6: % Change YoY | L6: 0.215 | M6: 0.151 | N6: 0.143 | O6: 0.042 | P6: 0.033 | S6: Depreciation & Amortization | T6: 8.19 | U6: 8.5 | V6: 8.27 | W6: 7.51 | X6: 7.46 | Y6: 19.89 | AA6: Total Cash And Short Term Investments | AB6: 54.34 | AC6: 114.13 | AD6: 86.79 | AE6: 18.16 | AF6: 54.87
B7: % Change YoY | C7: 0.412 | D7: 0.409 | E7: 0.367 | F7: 0.497 | G7: -0.089 | H7: -0.026 | K7: EBITDA | L7: 126.13 | M7: 154.87 | N7: 190.25 | O7: 201.25 | P7: 196 | Q7: 0.117 | S7: Amortization of Goodwill and Intangible Assets | T7: 0.09 | V7: 0.07 | W7: 0.05 | X7: 0.05 | Y7: 0.16 | AA7: Accounts Receivable | AB7: 20.84 | AC7: 23.89 | AD7: 23.4 | AE7: 29.63 | AF7: 35.85
B8: Cost of Goods Sold | C8: -59.82 | D8: -70.82 | E8: -75.14 | F8: -102.02 | G8: -119.6 | H8: -123.52 | I8: -147.65 | K8: % Change YoY | L8: 0.156 | M8: 0.228 | N8: 0.228 | O8: 0.058 | P8: -0.026 | S8: Total Depreciation & Amortization | T8: 8.28 | U8: 8.5 | V8: 8.34 | W8: 7.55 | X8: 7.51 | Y8: 20.06 | AA8: Other Receivables | AB8: 12.21 | AC8: 4.07 | AD8: 13.21 | AE8: 28.22 | AF8: 30.42
B9: Gross Profit | C9: 32.85 | D9: 59.74 | E9: 103.31 | F9: 165.2 | G9: 123.79 | H9: 113.49 | I9: 119.97 | K9: % EBITDA Margins | L9: 0.438 | M9: 0.467 | N9: 0.502 | O9: 0.51 | P9: 0.48 | Q9: 0.023 | S9: (Gain) Loss From Sale Of Asset | T9: -0.24 | U9: 0.06 | V9: -1.96 | W9: -0.09 | X9: -0.53 | Y9: -0.11 | AA9: Notes Receivable | AB9: 0.02
B10: % Change YoY | C10: -0.04 | D10: 0.819 | E10: 0.729 | F10: 0.599 | G10: -0.251 | H10: -0.083 | K10: EBIT | L10: 109.13 | M10: 132.3 | N10: 158.33 | O10: 167.73 | P10: 170 | Q10: 0.117 | S10: (Gain) Loss on Sale of Investments | U10: 0.59 | AA10: Total Receivables | AB10: 33.06 | AC10: 27.96 | AD10: 36.61 | AE10: 57.85 | AF10: 66.27
B11: % Gross Margins | C11: 0.354 | D11: 0.458 | E11: 0.579 | F11: 0.618 | G11: 0.509 | H11: 0.479 | I11: 0.448 | K11: % Change YoY | L11: 0.137 | M11: 0.212 | N11: 0.197 | O11: 0.059 | P11: 0.014 | S11: Asset Writedown & Restructuring Costs | AA11: Inventory | AB11: 0.72 | AC11: 0.82 | AD11: 1.09 | AE11: 2 | AF11: 2.76 | AI11: =SUM(AD18+AD11+AD12+AD13) -> 2.84 | AJ11: =SUM(AE11+AE12+AE13) -> 4.05
B12: Selling General & Admin Expenses | C12: -6.29 | D12: -8.34 | E12: -8.8 | F12: -8.84 | G12: -10.12 | H12: -17.63 | I12: -21.85 | K12: % EBIT Margins | L12: 0.379 | M12: 0.399 | N12: 0.418 | O12: 0.425 | P12: 0.417 | Q12: 0.024 | S12: Other Operating Activities | T12: 3.52 | U12: 2.08 | V12: 0.22 | W12: -0.65 | X12: -1.71 | Y12: -3.87 | AA12: Prepaid Expenses | AB12: 0.17 | AC12: 0.15 | AD12: 0.37 | AE12: 0.36
B13: Depreciation & Amortization | K13: EBT Normalized | L13: 101.93 | M13: 127.41 | N13: 153.61 | O13: 188.6 | S13: Change In Accounts Receivable | T13: -3.64 | U13: -12.05 | V13: -9.14 | W13: 4.36 | X13: -6.91 | Y13: -22.04 | AA13: Other Current Assets | AB13: 0.95 | AC13: 0.04 | AD13: 0.55 | AE13: 1.69
B14: Amortization of Goodwill and Intangible Assets | K14: % Change YoY | L14: 0.044 | M14: 0.25 | N14: 0.206 | O14: 0.228 | S14: Change In Inventories | T14: -0.07 | U14: -0.04 | V14: 0.26 | W14: -0.09 | X14: -0.28 | Y14: 0.21 | AA14: Total Current Assets | AB14: 89.25 | AC14: 143.1 | AD14: 125.41 | AE14: 80.07 | AF14: 123.9
B15: Other Operating Expenses | C15: -0.04 | D15: -0.49 | E15: 0.71 | F15: -10.35 | G15: -2.06 | H15: -0.03 | I15: -3.97 | K15: % EBT Margins | L15: 0.354 | M15: 0.384 | N15: 0.405 | O15: 0.478 | S15: Change in Unearned Revenues | U15: -2.46 | V15: -3.49 | W15: -2.32 | X15: -2.26 | Y15: -7.4 | AA15: Gross Property Plant And Equipment | AB15: 206.26 | AC15: 192.65 | AD15: 228.96 | AE15: 320.09
B16: Total Operating Expenses | C16: -6.33 | D16: -8.83 | E16: -8.09 | F16: -19.19 | G16: -12.19 | H16: -17.67 | I16: -25.83 | K16: Net Income Normalized | L16: 80.83 | M16: 102.63 | N16: 120.07 | O16: 136.35 | S16: Change in Other Net Operating Assets | T16: -0.84 | U16: 4.16 | V16: 1.21 | W16: 12.92 | X16: 3.92 | Y16: 2.17 | AA16: Accumulated Depreciation | AB16: -90.27 | AC16: -80.57 | AD16: -85.62 | AE16: -104.29
B17: Operating Income | C17: 26.52 | D17: 50.91 | E17: 95.23 | F17: 146 | G17: 111.6 | H17: 95.82 | I17: 94.14 | K17: % Change YoY | L17: 0.025 | M17: 0.27 | N17: 0.17 | O17: 0.136 | S17: Cash from Operations | T17: 27.54 | U17: 40.92 | V17: 74.16 | W17: 136.67 | X17: 91.91 | Y17: 67.87 | AA17: Net Property Plant And Equipment | AB17: 115.98 | AC17: 112.08 | AD17: 143.35 | AE17: 215.8 | AF17: 304.33
B18: % Change YoY | C18: 1.531 | D18: 0.92 | E18: 0.87 | F18: 0.533 | G18: -0.236 | H18: -0.141 | K18: % Net Income Margins | L18: 0.281 | M18: 0.31 | N18: 0.317 | O18: 0.345 | S18: Memo: Change in Net Working Capital | T18: -4.54 | U18: -10.39 | V18: -11.16 | W18: 14.87 | X18: -5.51 | Y18: -27.07 | AA18: Goodwill | AB18: 0.83 | AC18: 0.83 | AD18: 0.83 | AE18: 40.04 | AF18: 40.04
B19: % Operating Margins | C19: 0.286 | D19: 0.39 | E19: 0.534 | F19: 0.546 | G19: 0.459 | H19: 0.404 | I19: 0.352 | K19: EPS Normalized | L19: 23.34 | M19: 29.14 | N19: 32.04 | S19: Capital Expenditure | T19: -1.79 | U19: -1.74 | V19: -1.92 | W19: -1.77 | X19: -11.2 | Y19: -62.56 | AA19: Other Intangibles | AB19: 0.64 | AC19: 0.61 | AD19: 0.61 | AE19: 1.91 | AF19: 2.86
B20: Interest Expense | C20: -1.3 | D20: -0.79 | E20: -0.42 | F20: -2.18 | G20: -0.48 | H20: -1.44 | I20: -4.99 | K20: % Change YoY | L20: 0.04 | M20: 0.249 | N20: 0.1 | S20: Sale of Property, Plant, and Equipment | T20: 0.71 | U20: 0.17 | V20: 12.15 | W20: 0.41 | X20: 0.86 | Y20: 3 | AA20: Deferred Tax Assets Long-Term
B21: Interest And Investment Income | C21: 0.04 | D21: 0.3 | E21: 0.17 | F21: 0.08 | G21: 2.34 | H21: 3.3 | I21: 1.13 | K21: EPS (GAAP) | L21: 23.34 | M21: 29.14 | N21: 32.04 | S21: Cash Acquisitions | Y21: -29.27 | AA21: Other Long-Term Assets | AB21: 2.37 | AC21: 2.94 | AD21: 1.19 | AE21: 0.62 | AF21: 0.41
B22: Currency Exchange Gains (Loss) | C22: 0.05 | D22: -0.05 | E22: 0.18 | F22: -0.03 | G22: 0.02 | H22: -0.23 | I22: -0.23 | K22: % Change YoY | L22: 0.04 | M22: 0.249 | N22: 0.1 | S22: Investment in Marketable and Equity Securities | V22: -5 | W22: 5 | AA22: Total Assets | AB22: 209.07 | AC22: 259.56 | AD22: 271.39 | AE22: 338.44 | AF22: 471.53
B23: Other Non Operating Income (Expenses) | C23: -0.02 | D23: -0.01 | E23: -0.01 | F23: -0.02 | H23: 0 | I23: 0 | K23: Free Cash Flow | L23: -2 | M23: 65.5 | N23: 99 | O23: 130 | P23: 133.5 | S23: Net (Increase) Decrease in Loans Originated / Sold - Investing | Y23: -1.5 | AA23: Accounts Payable | AB23: 5.95 | AC23: 10.83 | AD23: 12.69 | AE23: 15.87 | AF23: 17.55
B24: EBT Excl. Unusual Items | C24: 25.29 | D24: 50.35 | E24: 95.16 | F24: 143.86 | G24: 113.48 | H24: 97.45 | I24: 90.05 | K24: % Change YoY | L24: -1.377 | M24: 33.75 | N24: 0.511 | O24: 0.313 | P24: 0.027 | S24: Other Investing Activities | X24: 2.29 | Y24: 3.5 | AA24: Accrued Expenses | AB24: 3.85 | AC24: 3.66 | AD24: 3.42 | AE24: 1.15 | AF24: 1.21
B25: Gain (Loss) On Sale Of Investments | D25: -0.59 | K25: % Free Cash Flow Margins | L25: -0.007 | M25: 0.198 | N25: 0.261 | O25: 0.329 | P25: 0.327 | S25: Cash from Investing | T25: -1.08 | U25: -1.57 | V25: 5.24 | W25: 3.64 | X25: -8.05 | Y25: -86.84 | AA25: Short-term Borrowings
B26: Gain (Loss) On Sale Of Assets | C26: 0.25 | D26: -0.05 | E26: 1.99 | F26: 0.09 | G26: 0.57 | H26: 0.14 | I26: 0.14 | K26: Dividend Per Share | L26: 12.76 | M26: 20.6 | N26: 24.19 | S26: Total Debt Issued | V26: 0.18 | AA26: Current Portion of Long-Term Debt | AB26: 4.32 | AC26: 0.05 | AD26: 0.02 | AE26: 3.51 | AF26: 14.11
B27: Asset Writedown | K27: % Change YoY | L27: -0.031 | M27: 0.614 | N27: 0.174 | S27: Total Debt Repaid | T27: -11.04 | U27: -8.79 | V27: -9.05 | W27: -4.71 | X27: -0.5 | Y27: -2.95 | AA27: Current Portion of Capital Lease Obligations | AB27: 0.19 | AC27: 0.35 | AD27: 0.32 | AE27: 2.76 | AF27: 6.6 | AH27: =SUM(AD26:AD29) -> 3.73
B28: Legal Settlements | C28: -0.13 | D28: -0.06 | E28: 0 | F28: -0.15 | G28: -0.22 | H28: 0.01 | I28: 0.01 | K28: IS Supplementary Data: | S28: Issuance of Common Stock | AA28: Current Income Taxes Payable | AB28: 2.99 | AC28: 1.62 | AD28: 1.26 | AE28: 1.27 | AF28: 2.21
B29: Other Unusual Items | C29: -0.07 | D29: -0.03 | E29: -0.04 | K29: Gross Margin (%) | L29: 46.9 | M29: 48.5 | N29: 48.7 | S29: Repurchase of Common Stock | T29: -1.99 | U29: -7.54 | V29: 0 | AA29: Unearned Revenue Current | AB29: 2.2 | AC29: 2.14 | AD29: 2.13 | AE29: 2.59 | AF29: 1.29
B30: EBT Incl. Unusual Items | C30: 25.34 | D30: 49.63 | E30: 97.12 | F30: 143.8 | G30: 113.82 | H30: 97.6 | I30: 90.2 | K30: Interest Expense | L30: -3.48 | M30: -2.3 | N30: -1.92 | O30: -0.6 | S30: Common Dividends Paid | U30: -9.68 | V30: -48.34 | W30: -70.78 | X30: -110.66 | Y30: -46.26 | AA30: Other Current Liabilities | AB30: 0.2 | AC30: 5.27 | AD30: 40.39 | AE30: 28.75 | AF30: 62.37
B31: Income Tax Expense | C31: -4.82 | D31: -9.54 | E31: -18.39 | F31: -28.81 | G31: -21.66 | H31: -18.73 | I31: -17.84 | K31: Depreciation & Amortization | L31: 17.09 | M31: 21.93 | N31: 22.76 | O31: 22.65 | P31: 22 | Q31: 0.065 | S31: Common & Preferred Stock Dividends Paid | U31: -9.68 | V31: -48.34 | W31: -70.78 | X31: -110.66 | Y31: -46.26 | AA31: Total Current Liabilities | AB31: 19.71 | AC31: 23.92 | AD31: 60.23 | AE31: 55.91 | AF31: 105.35
B32: Earnings From Continuing Operations | C32: 20.52 | D32: 40.09 | E32: 78.73 | F32: 114.99 | G32: 92.15 | H32: 78.86 | I32: 72.35 | K32: % Change YoY | L32: 0.302 | M32: 0.283 | N32: 0.038 | O32: -0.005 | P32: -0.029 | S32: Other Financing Activities | T32: -1.3 | U32: -0.73 | V32: -0.26 | W32: -0.03 | X32: -0.04 | Y32: -0.44 | AA32: Long-Term Debt | AB32: 0.06 | AC32: 0.02 | AE32: 4.21 | AF32: 37.99
B33: Net Income to Company | C33: 20.52 | D33: 40.09 | E33: 78.73 | F33: 114.99 | G33: 92.15 | H33: 78.86 | I33: 72.35 | K33: Effective Tax Rate (%) | L33: 19 | M33: 19 | N33: 19 | O33: 19 | P33: 19 | S33: Cash from Financing | T33: -14.34 | U33: -26.74 | V33: -57.48 | W33: -75.52 | X33: -111.2 | Y33: -49.65 | AA33: Capital Leases | AB33: 1.21 | AC33: 1.58 | AD33: 1.64 | AE33: 16.33 | AF33: 56.15 | AH33: =AF33+AF32+AF37 -> 122.65
B34: Minority Interest | H34: 0 | I34: 0.1 | K34: EBT (GAAP) Actual | L34: 101.93 | M34: 127.41 | N34: 153.61 | O34: 188.6 | S34: Net Change in Cash | T34: 12.12 | U34: 12.61 | V34: 21.92 | W34: 64.78 | X34: -27.34 | Y34: -68.63 | AA34: Unearned Revenue Non Current | AB34: 19.19 | AC34: 16.93 | AD34: 14.69 | AE34: 6.85 | AF34: 5.8
B35: Net Income | C35: 20.52 | D35: 40.09 | E35: 78.73 | F35: 114.99 | G35: 92.15 | H35: 78.86 | I35: 72.45 | K35: % Change YoY | L35: 0.044 | M35: 0.25 | N35: 0.206 | O35: 0.228 | S35: Supplementary Data: | AA35: Pension & Other Post Retirement Benefits | AB35: 0.12 | AC35: 0.12 | AD35: 0.17 | AE35: 0.3 | AF35: 0.29
B36: Net Income to Common Incl Extra Items | C36: 20.52 | D36: 40.09 | E36: 78.73 | F36: 114.99 | G36: 92.15 | H36: 78.86 | I36: 72.45 | K36: Net Income (GAAP) | L36: 80.83 | M36: 102.63 | N36: 120.07 | O36: 136.35 | S36: Free Cash Flow | T36: 25.74 | U36: 39.18 | V36: 72.25 | W36: 134.9 | X36: 80.71 | Y36: 5.3 | AA36: Deferred Tax Liability Non Current | AB36: 6.18 | AC36: 5.51 | AD36: 6.4 | AE36: 5.58 | AF36: 6.88
B37: % Net Income to Common Incl Extra Items Margins | C37: 0.221 | D37: 0.307 | E37: 0.441 | F37: 0.43 | G37: 0.379 | H37: 0.333 | I37: 0.271 | K37: % Change YoY | L37: 0.025 | M37: 0.27 | N37: 0.17 | O37: 0.136 | S37: % Change YoY | T37: 1.326 | U37: 0.522 | V37: 0.844 | W37: 0.867 | X37: -0.402 | Y37: -0.934 | AA37: Other Non Current Liabilities | AB37: 0.03 | AC37: 4.72 | AE37: 27.46 | AF37: 28.51 | AG37: what is this?
B38: Net Income to Common Excl. Extra Items | C38: 20.52 | D38: 40.09 | E38: 78.73 | F38: 114.99 | G38: 92.15 | H38: 78.86 | I38: 72.45 | K38: Cash EPS | L38: 34.8 | M38: 33.8 | S38: % Free Cash Flow Margins | T38: 0.278 | U38: 0.3 | V38: 0.405 | W38: 0.505 | X38: 0.332 | Y38: 0.022 | AA38: Total Liabilities | AB38: 46.5 | AC38: 52.79 | AD38: 83.13 | AE38: 116.65 | AF38: 240.96 | AH38: =AF38-AF33-AF31 -> 79.46 | AJ38: 81
B39: % Net Income to Common Excl. Extra Items Margins | C39: 0.221 | D39: 0.307 | E39: 0.441 | F39: 0.43 | G39: 0.379 | H39: 0.333 | I39: 0.271 | K39: % Change YoY | M39: -0.029 | S39: Cash and Cash Equivalents, Beginning of Period | T39: 2.68 | U39: 14.8 | V39: 27.42 | W39: 49.34 | X39: 114.13 | Y39: 86.79 | AA39: Common Stock | AB39: 35.13 | AC39: 35.13 | AD39: 35.13 | AE39: 35.13 | AF39: 35.13
B40: Supplementary Data: | K40: CF Supplementary Data: | S40: Cash and Cash Equivalents, End of Period | T40: 14.8 | U40: 27.42 | V40: 49.34 | W40: 114.13 | X40: 86.79 | Y40: 18.16 | AA40: Additional Paid In Capital | AB40: 25.57 | AC40: 25.57 | AD40: 25.57 | AE40: 25.57 | AF40: 25.57
B41: Diluted EPS Excl Extra Items | C41: 5.68 | D41: 11.15 | E41: 22.12 | F41: 32.73 | G41: 26.23 | H41: 22.45 | I41: 20.62 | K41: Cash From Operations | L41: 114.51 | M41: 119.79 | N41: 142.1 | O41: 173.7 | S41: Cash Interest Paid | T41: 1.3 | U41: 0.73 | V41: 0.26 | W41: 0.03 | X41: 0.04 | Y41: 0.44 | AA41: Retained Earnings | AB41: 100.88 | AC41: 145.08 | AD41: 126.58 | AE41: 159.18 | AF41: 168.06
B42: % Change YoY | C42: 1.977 | D42: 0.963 | E42: 0.983 | F42: 0.48 | G42: -0.199 | H42: -0.144 | K42: % Change YoY | L42: 0.687 | M42: 0.046 | N42: 0.186 | O42: 0.222 | S42: Cash Taxes Paid | T42: 2.6 | U42: 8.18 | V42: 18.43 | W42: 29.48 | X42: 21.13 | Y42: 19.55 | AA42: Comprehensive Income and Other | AB42: 0.99 | AC42: 0.99 | AD42: 0.99 | AE42: 0.99 | AF42: 0.99
...

Sheet  APV
B1: Mo-Bruk SA | C1: Previous report: Q3 2024 | E1: Discounting factor
E2: 1 | F2: 2 | G2: 3 | H2: 4 | I2: 5
D3: 2024 E | E3: 2025E | F3: 2026E | G3: 2027E | H3: 2028E | I3: 2029E | J3: AVG
B5: Revenue | D5: ='Main LBO'!G62 -> 288 | E5: ='Main LBO'!H62 -> 351.648 | F5: ='Main LBO'!I62 -> 393.14246 | G5: ='Main LBO'!J62 -> 436.78128 | H5: ='Main LBO'!K62 -> 482.20653 | I5: ='Main LBO'!L62 -> 532.83822
B6: % growth | E6: =(E5-D5)/D5 -> 0.221 | F6: =(F5-E5)/E5 -> 0.118 | G6: 0.06 | H6: 0.06 | I6: 0.06 | J6: =AVERAGE(E6:I6) -> 0.1038
B8: Operating Income (EBIT) | D8: ='Main LBO'!G74 -> 114.52 | E8: ='Main LBO'!H74 -> 139.76762 | F8: ='Main LBO'!I74 -> 162.55048 | G8: ='Main LBO'!J74 -> 181.46715 | H8: ='Main LBO'!K74 -> 200.33973 | I8: ='Main LBO'!L74 -> 221.3754
B9: % of revenue | E9: =E8/E5 -> 0.39746457 | F9: =F8/F5 -> 0.41346457 | G9: =F9 -> 0.41346457 | H9: =G9 -> 0.41346457 | I9: =H9 -> 0.41346457 | J9: =AVERAGE(E9:I9) -> 0.41026457
B11: (-) Taxes | D11: ='Main LBO'!G83 -> 17.84 | E11: ='Main LBO'!H83 -> 12.259355 | F11: ='Main LBO'!I83 -> 17.270079 | G11: ='Main LBO'!J83 -> 21.921063 | H11: ='Main LBO'!K83 -> 26.885783 | I11: ='Main LBO'!L83 -> 32.586178
B12: % tax rate | E12: 0.19 | F12: 0.19 | G12: 0.19 | H12: 0.19 | I12: 0.19 | J12: =AVERAGE(E12:I12) -> 0.19
B14: EBIAT (EBIT after tax) | D14: =D8-D11 -> 96.68 | E14: =E8-E11 -> 127.50827 | F14: =F8-F11 -> 145.2804 | G14: =G8-G11 -> 159.54608 | H14: =H8-H11 -> 173.45395 | I14: =I8-I11 -> 188.78922
B16: (+) D&A | E16: ='Main LBO'!H92 -> 16.84907 | F16: ='Main LBO'!I92 -> 18.83726 | G16: ='Main LBO'!J92 -> 20.928196 | H16: ='Main LBO'!K92 -> 23.104728 | I16: ='Main LBO'!L92 -> 25.530724
B17: % of CAPX | E17: =E16/E5 -> 0.04791459 | F17: =F16/F5 -> 0.04791459 | G17: =F17 -> 0.04791459 | H17: =G17 -> 0.04791459 | I17: =H17 -> 0.04791459 | J17: =AVERAGE(E17:I17) -> 0.04791459
B19: (-) CapEx | E19: ='Main LBO'!H95 -> 28.13184 | F19: ='Main LBO'!I95 -> 23.588548 | G19: ='Main LBO'!J95 -> 21.839064 | H19: ='Main LBO'!K95 -> 24.110327 | I19: ='Main LBO'!L95 -> 26.641911
B20: % of revenue | E20: =E19/E5 -> 0.08 | F20: =F19/F5 -> 0.06 | G20: =G19/G5 -> 0.05 | H20: =H19/H5 -> 0.05 | I20: =I19/I5 -> 0.05 | J20: =AVERAGE(E20:I20) -> 0.058
B22: Change in net working capital | E22: ='Main LBO'!H89 -> 9.5184126 | F22: ='Main LBO'!I89 -> 10.641585 | G22: ='Main LBO'!J89 -> 11.822801 | H22: ='Main LBO'!K89 -> 13.052373 | I22: ='Main LBO'!L89 -> 14.422872
B23: % of revenue | E23: =E22/E5 -> 0.027068013 | F23: =F22/F5 -> 0.027068013 | G23: =G22/G5 -> 0.027068013 | H23: =H22/H5 -> 0.027068013 | I23: =I22/I5 -> 0.027068013 | J23: =AVERAGE(E23:I23) -> 0.027068013
B25: FCFF (unlevered, no interest deducted) | E25: =E14+E16-E19-E22 -> 106.70708 | F25: =F14+F16-F19-F22 -> 129.88753 | G25: =G14+G16-G19-G22 -> 146.81241 | H25: =H14+H16-H19-H22 -> 159.39597 | I25: =I14+I16-I19-I22 -> 173.25516
B26: Unlevered Cost of Capital (tax shield not included) | E26: =' WACC & Unlevered CoC'!$G$34 -> 0.1014338 | F26: =' WACC & Unlevered CoC'!$G$34 -> 0.1014338 | G26: =' WACC & Unlevered CoC'!$G$34 -> 0.1014338 | H26: =' WACC & Unlevered CoC'!$G$34 -> 0.1014338 | I26: =' WACC & Unlevered CoC'!$G$34 -> 0.1014338
B27: PV of FCFF | E27: =E25/(1+E26)^E2 -> 96.880161 | F27: =F25/(1+F26)^F2 -> 107.06577 | G27: =G25/(1+G26)^G2 -> 109.87214 | H27: =H25/(1+H26)^H2 -> 108.30381 | I27: =I25/(1+I26)^I2 -> 106.87944
B29: Interest cost | E29: ='Main LBO'!H77 -> 75.793402 | F29: ='Main LBO'!I77 -> 72.20403 | G29: ='Main LBO'!J77 -> 66.641832 | H29: ='Main LBO'!K77 -> 59.384307 | I29: ='Main LBO'!L77 -> 50.417899
B30: Tax shield | E30: =E29*E12 -> 14.400746 | F30: =F29*F12 -> 13.718766 | G30: =G29*G12 -> 12.661948 | H30: =H29*H12 -> 11.283018 | I30: =I29*I12 -> 9.5794008
B31: Cost of debt | E31: =' WACC & Unlevered CoC'!G48 -> 0.083187 | F31: =' WACC & Unlevered CoC'!H48 -> 0.071685 | G31: =' WACC & Unlevered CoC'!I48 -> 0.068526 | H31: =' WACC & Unlevered CoC'!J48 -> 0.062208 | I31: =' WACC & Unlevered CoC'!K48 -> 0.057105 | J31: Adjusted based on Aswath Damodarans ICR risk premiums
B32: Pv of tax shield | E32: =E30/(1+E31)^E2 -> 13.294792 | F32: =F30/(1+F31)^F2 -> 11.944851 | G32: =G30/(1+G31)^G2 -> 10.378755 | H32: =H30/(1+H31)^H2 -> 8.8631279 | I32: =I30/(1+I31)^I2 -> 7.2568427
G34: Valuation
G35: Terminal value | I35: =(I25*(1+I56)/(I55-I56)) -> 2170.1095
G36: PV of terminal value | I36: =I35/(1+I55)^I2 -> 1338.7197
G37: PV of FCFF | I37: =SUM(E27:I27) -> 529.00133
G38: PV of tax shield | I38: =SUM(E32:I32) -> 51.738369
G39: Terminal value Ts | I39: =(I30*(1+I56)/(I31-I56)) -> 263.33348
G40: PV terminal value Ts | I40: =I39/(1+I31)^I2 -> 199.48739
G41: APV (EV) | I41: =I37+I38+I40+I36 -> 2118.9468
G42: Cash & cash equivalents | I42: ='Main LBO'!E19 -> 54.87
G43: Debt | I43: ='Main LBO'!E18 -> 142.311
G44: Equity value | I44: =I41+I42-I43 -> 2031.5058
G45: Shares outstanding (m) | I45: 3.51
G46: Price target | I46: =I44/I45 -> 578.77657
G48: Reference price (offer) | I48: ='Main LBO'!L10 -> 404.5815
G49: Premium to the offer | I49: =(I46/I48)-1 -> 0.4305562
G51: Current share price | I51: 305
G52: Upside | I52: =(I46-I51) -> 273.77657
...

Sheet  WACC & Unlevered CoC
J3: Polish 10 Year Government Bond | K3: 2018 | L3: 2019 | M3: 2020 | N3: 2021 | O3: 2022 | P3: 2023 | Q3: 2024 | R3: 2025
B4: Cost of Debt | F4: 1. | G4: Interest coverage | H4: Risk premium | J4: December | K4: 0.02846 | L4: 0.0213 | M4: 0.01252 | N4: 0.03705 | O4: 0.06878 | P4: 0.05248 | Q4: 0.05888
B5: Long Term risk free rate | D5: =R13 -> 0.05845 | G5: <0,5 | H5: 0.19 | J5: November | K5: 0.03044 | L5: 0.02014 | M5: 0.01236 | N5: 0.0311 | O5: 0.06616 | P5: 0.05517 | Q5: 0.05519
G6: 0.5 | H6: 0.155 | J6: October | K6: 0.03209 | L6: 0.01965 | M6: 0.01187 | N6: 0.02877 | O6: 0.08393 | P6: 0.05665 | Q6: 0.05906
B7: EBIT | D7: 115 | G7: 0.8 | H7: 0.101 | J7: September | K7: 0.03235 | L7: 0.01995 | M7: 0.01313 | N7: 0.02189 | O7: 0.07164 | P7: 0.05916 | Q7: 0.05307
B8: Interest costs | D8: ='Main LBO'!G77 -> 4.99 | G8: 1.25 | H8: 0.0728 | J8: August | K8: 0.03183 | L8: 0.01832 | M8: 0.01392 | N8: 0.01837 | O8: 0.06164 | P8: 0.05591 | Q8: 0.05464
B9: Interest coverage ratio | D9: =D7/D8 -> 23.046092 | G9: 1.5 | H9: 0.0442 | J9: July | K9: 0.03187 | L9: 0.02177 | M9: 0.01285 | N9: 0.01714 | O9: 0.05559 | P9: 0.05431 | Q9: 0.05379
B10: Spread (Risk premium) | D10: =IF(D9<$G$6,$H$5,IF(D9<$G$7,$H$6,IF(D9<$G$8,$H$7,IF(D9<$G$9,$H$8,IF(D9<$G$10,$H$9,IF(D9<$G$11,$H$10,IF(D9<$G$12,$H$11,IF(D9<$G$13,$H$12,IF(D9<$G$14,$H$13,IF(D9<$G$15,$H$14,IF(D9<$G$16,$H$15,IF(D9<$G$17,$H$16,IF(D9<$G$18,$H$17,IF(D9<$G$19,$H$18,IF(D9>$G$19,$H$19))))))))))))))) -> 0.0045 | G10: 2 | H10: 0.03 | J10: June | K10: 0.03212 | L10: 0.02394 | M10: 0.01385 | N10: 0.0165 | O10: 0.06936 | P10: 0.05776 | Q10: 0.057
G11: 2.5 | H11: 0.0261 | J11: May | K11: 0.03275 | L11: 0.02649 | M11: 0.01185 | N11: 0.01866 | O11: 0.06627 | P11: 0.06045 | Q11: 0.05708
B12: Cost of Debt before Tax | D12: =D10+D5 -> 0.06295 | G12: 3 | H12: 0.0183 | J12: April | K12: 0.03076 | L12: 0.0301 | M12: 0.01464 | N12: 0.01715 | O12: 0.06399 | P12: 0.05909 | Q12: 0.05722
B13: Tax rate | D13: 0.19 | G13: 3.5 | H13: 0.0155 | J13: March | K13: 0.03167 | L13: 0.0284 | M13: 0.01685 | N13: 0.01575 | O13: 0.05242 | P13: 0.06065 | Q13: 0.05443 | R13: 0.05845
G14: 4 | H14: 0.012 | J14: February | K14: 0.0335 | L14: 0.02954 | M14: 0.01792 | N14: 0.01607 | O14: 0.04116 | P14: 0.06555 | Q14: 0.05323 | R14: 0.05845
B15: Cost of Debt after Tax | D15: =D12*(1-D13) -> 0.0509895 | G15: 4.5 | H15: 0.0095 | J15: January | K15: 0.03621 | L15: 0.02731 | M15: 0.02132 | N15: 0.01161 | O15: 0.0411 | P15: 0.06048 | Q15: 0.0521 | R15: 0.05845
G16: 6 | H16: 0.0085 | J16: Average | K16: =AVERAGE(K4:K15) -> 0.032004167 | L16: =AVERAGE(L4:L15) -> 0.023909167 | M16: =AVERAGE(M4:M15) -> 0.014423333 | N16: =AVERAGE(N4:N15) -> 0.020838333 | O16: =AVERAGE(O4:O15) -> 0.061836667 | P16: =AVERAGE(P4:P15) -> 0.058138333 | Q16: =AVERAGE(Q4:Q15) -> 0.055474167 | R16: =AVERAGE(R13:R15) -> 0.05845
B17: Cost of Equity | D17: capm | G17: 7.5 | H17: 0.0077
B18: Beta | D18: ='Baseline Beta'!H4 -> 0.44142382 | G18: 9.5 | H18: 0.006
B19: Adjusted Beta | D19: =D18*(1/3)+1*(2/3) -> 0.81380794 | G19: 12.5 | H19: 0.0045
B20: Long Term risk free rate | D20: =D5 -> 0.05845 | G20: Source: Aswath Damodaran
B21: Expected return | D21: ='Expected Return'!P7 -> 0.104
B22: MRP | D22: 0.0584 | E22: =D21-D20 -> 0.04555
B24: Cost of Equity | D24: =D20+(D19*D22) -> 0.10597638 | F24: APV method
B26: WACC | F26: Unlevered Cost of Capital
B27: EV | D27: =D29-'Main LBO'!L17+'Main LBO'!L16 -> 1178.1918 | F27: Tax rate | G27: ='Main LBO'!H84 -> 0.19
F28: Debt | G28: ='Main LBO'!L16 -> 142.311
B29: Market cap | D29: ='Main LBO'!E14 -> 1090.7508 | F29: Market cap | G29: ='Main LBO'!E14 -> 1090.7508
B30: % av EV | D30: =D29/D27 -> 0.92578373 | F30: Debt/Equity Ratio | G30: =G28/G29 -> 0.13047068
B31: Debt | D31: ='Main LBO'!L16 -> 142.311 | F31: Adjusted Beta | G31: =D19 -> 0.81380794
B32: % av EV | D32: =D31/D27 -> 0.12078763 | F32: Unlevered Beta | G32: =G31/(1+(1-G27)*G30) -> 0.736024
B34: WACC | D34: =D30*D24+D32*D15 -> 0.10427011 | F34: Unlevered Cost of Equity | G34: =D20+(G32*D22) -> 0.1014338
F37: Cost of Debt | G37: 2025 | H37: 2026 | I37: 2027 | J37: 2028 | K37: 2029
F38: Long Term risk free rate | G38: 0.0585 | H38: 0.0585 | I38: 0.0585 | J38: 0.0585 | K38: 0.0585
F40: EBIT | G40: ='Main LBO'!H74 -> 139.76762 | H40: ='Main LBO'!I74 -> 162.55048 | I40: ='Main LBO'!J74 -> 181.46715 | J40: ='Main LBO'!K74 -> 200.33973 | K40: ='Main LBO'!L74 -> 221.3754
F41: Interest costs | G41: ='Main LBO'!H171 -> 75.793402 | H41: ='Main LBO'!I171 -> 72.20403 | I41: ='Main LBO'!J171 -> 66.641832 | J41: ='Main LBO'!K171 -> 59.384307 | K41: ='Main LBO'!L171 -> 50.417899
F42: Interest coverage ratio | G42: =G40/G41 -> 1.8440605 | H42: =H40/H41 -> 2.251266 | I42: =I40/I41 -> 2.7230216 | J42: =J40/J41 -> 3.373614 | K42: =K40/K41 -> 4.3908097
F43: Spread (Risk premium) | G43: =IF(G42<$G$6,$H$5,IF(G42<$G$7,$H$6,IF(G42<$G$8,$H$7,IF(G42<$G$9,$H$8,IF(G42<$G$10,$H$9,IF(G42<$G$11,$H$10,IF(G42<$G$12,$H$11,IF(G42<$G$13,$H$12,IF(G42<$G$14,$H$13,IF(G42<$G$15,$H$14,IF(G42<$G$16,$H$15,IF(G42<$G$17,$H$16,IF(G42<$G$18,$H$17,IF(G42<$G$19,$H$18,IF(G42>$G$19,$H$19))))))))))))))) -> 0.0442 | H43: =IF(H42<$G$6,$H$5,IF(H42<$G$7,$H$6,IF(H42<$G$8,$H$7,IF(H42<$G$9,$H$8,IF(H42<$G$10,$H$9,IF(H42<$G$11,$H$10,IF(H42<$G$12,$H$11,IF(H42<$G$13,$H$12,IF(H42<$G$14,$H$13,IF(H42<$G$15,$H$14,IF(H42<$G$16,$H$15,IF(H42<$G$17,$H$16,IF(H42<$G$18,$H$17,IF(H42<$G$19,$H$18,IF(H42>$G$19,$H$19))))))))))))))) -> 0.03 | I43: =IF(I42<$G$6,$H$5,IF(I42<$G$7,$H$6,IF(I42<$G$8,$H$7,IF(I42<$G$9,$H$8,IF(I42<$G$10,$H$9,IF(I42<$G$11,$H$10,IF(I42<$G$12,$H$11,IF(I42<$G$13,$H$12,IF(I42<$G$14,$H$13,IF(I42<$G$15,$H$14,IF(I42<$G$16,$H$15,IF(I42<$G$17,$H$16,IF(I42<$G$18,$H$17,IF(I42<$G$19,$H$18,IF(I42>$G$19,$H$19))))))))))))))) -> 0.0261 | J43: =IF(J42<$G$6,$H$5,IF(J42<$G$7,$H$6,IF(J42<$G$8,$H$7,IF(J42<$G$9,$H$8,IF(J42<$G$10,$H$9,IF(J42<$G$11,$H$10,IF(J42<$G$12,$H$11,IF(J42<$G$13,$H$12,IF(J42<$G$14,$H$13,IF(J42<$G$15,$H$14,IF(J42<$G$16,$H$15,IF(J42<$G$17,$H$16,IF(J42<$G$18,$H$17,IF(J42<$G$19,$H$18,IF(J42>$G$19,$H$19))))))))))))))) -> 0.0183 | K43: =IF(K42<$G$6,$H$5,IF(K42<$G$7,$H$6,IF(K42<$G$8,$H$7,IF(K42<$G$9,$H$8,IF(K42<$G$10,$H$9,IF(K42<$G$11,$H$10,IF(K42<$G$12,$H$11,IF(K42<$G$13,$H$12,IF(K42<$G$14,$H$13,IF(K42<$G$15,$H$14,IF(K42<$G$16,$H$15,IF(K42<$G$17,$H$16,IF(K42<$G$18,$H$17,IF(K42<$G$19,$H$18,IF(K42>$G$19,$H$19))))))))))))))) -> 0.012
F45: Cost of Debt before Tax | G45: =G43+G38 -> 0.1027 | H45: =H43+H38 -> 0.0885 | I45: =I43+I38 -> 0.0846 | J45: =J43+J38 -> 0.0768 | K45: =K43+K38 -> 0.0705
F46: Tax rate | G46: 0.19 | H46: 0.19 | I46: 0.19 | J46: 0.19 | K46: 0.19
F48: Cost of Debt after Tax | G48: =G45*(1-G46) -> 0.083187 | H48: =H45*(1-H46) -> 0.071685 | I48: =I45*(1-I46) -> 0.068526 | J48: =J45*(1-J46) -> 0.062208 | K48: =K45*(1-K46) -> 0.057105

Sheet Baseline Beta
A1: 10 years | B1: Mo-Bruk | D1: Warsaw Stock Exchange WIG
A2: Date | B2: Mo-Bruk | C2: Log return | D2: Closeprice | E2: Log return
A3: 03/20/2025 | B3: 327 | D3: 97258.96
A4: 03/19/2025 | B4: 327 | C4: =LN(B4)-LN(B3) -> 0 | D4: 98439.39 | E4: =LN(D4)-LN(D3) -> 0.012063917 | G4: Beta: | H4: =H25 -> 0.44142382
A5: 03/18/2025 | B5: 324 | C5: =LN(B5)-LN(B4) -> -0.0092166551 | D5: 98770.37 | E5: =LN(D5)-LN(D4) -> 0.0033566322
A6: 03/17/2025 | B6: 322 | C6: =LN(B6)-LN(B5) -> -0.0061919702 | D6: 98011.87 | E6: =LN(D6)-LN(D5) -> -0.0077090672
A7: 03/14/2025 | B7: 320 | C7: =LN(B7)-LN(B6) -> -0.0062305498 | D7: 97045.24 | E7: =LN(D7)-LN(D6) -> -0.0099113323
A8: 03/13/2025 | B8: 323.5 | C8: =LN(B8)-LN(B7) -> 0.010878118 | D8: 94955.29 | E8: =LN(D8)-LN(D7) -> -0.021771112 | G8: SUMMARY OUTPUT
A9: 03/12/2025 | B9: 322 | C9: =LN(B9)-LN(B8) -> -0.0046475684 | D9: 93428.42 | E9: =LN(D9)-LN(D8) -> -0.016210568
A10: 03/11/2025 | B10: 317 | C10: =LN(B10)-LN(B9) -> -0.015649772 | D10: 91991 | E10: =LN(D10)-LN(D9) -> -0.015504835 | G10: Regression Statistics
A11: 03/10/2025 | B11: 325 | C11: =LN(B11)-LN(B10) -> 0.024923408 | D11: 92203.3 | E11: =LN(D11)-LN(D10) -> 0.0023051755 | G11: Multiple R | H11: 0.16764046
A12: 03/07/2025 | B12: 328 | C12: =LN(B12)-LN(B11) -> 0.0091884261 | D12: 93611.8 | E12: =LN(D12)-LN(D11) -> 0.015160522 | G12: R Square | H12: 0.028103323
A13: 03/06/2025 | B13: 326.5 | C13: =LN(B13)-LN(B12) -> -0.0045836597 | D13: 93444.96 | E13: =LN(D13)-LN(D12) -> -0.0017838441 | G13: Adjusted R Square | H13: 0.02759607
A14: 03/05/2025 | B14: 330 | C14: =LN(B14)-LN(B13) -> 0.010662706 | D14: 92060.85 | E14: =LN(D14)-LN(D13) -> -0.014922828 | G14: Standard Error | H14: 0.035921525
A15: 03/04/2025 | B15: 325 | C15: =LN(B15)-LN(B14) -> -0.015267472 | D15: 89280.31 | E15: =LN(D15)-LN(D14) -> -0.030668801 | G15: Observations | H15: 1918
A16: 03/03/2025 | B16: 337 | C16: =LN(B16)-LN(B15) -> 0.036257748 | D16: 92526.5 | E16: =LN(D16)-LN(D15) -> 0.035714119
A17: 02/28/2025 | B17: 333.5 | C17: =LN(B17)-LN(B16) -> -0.010440065 | D17: 91996.4 | E17: =LN(D17)-LN(D16) -> -0.0057456441 | G17: ANOVA
A18: 02/27/2025 | B18: 338 | C18: =LN(B18)-LN(B17) -> 0.01340303 | D18: 92380.21 | E18: =LN(D18)-LN(D17) -> 0.0041633324 | H18: df | I18: SS | J18: MS | K18: F | L18: Significance F
A19: 02/26/2025 | B19: 346 | C19: =LN(B19)-LN(B18) -> 0.02339288 | D19: 93267.22 | E19: =LN(D19)-LN(D18) -> 0.0095559281 | G19: Regression | H19: 1 | I19: 0.071489558 | J19: 0.071489558 | K19: 55.402974 | L19: 1.4752111e-13
A20: 02/25/2025 | B20: 345 | C20: =LN(B20)-LN(B19) -> -0.002894358 | D20: 91730.25 | E20: =LN(D20)-LN(D19) -> -0.016616501 | G20: Residual | H20: 1916 | I20: 2.472322 | J20: 0.001290356
A21: 02/24/2025 | B21: 351 | C21: =LN(B21)-LN(B20) -> 0.017241806 | D21: 91306.52 | E21: =LN(D21)-LN(D20) -> -0.0046300069 | G21: Total | H21: 1917 | I21: 2.5438116
A22: 02/21/2025 | B22: 350 | C22: =LN(B22)-LN(B21) -> -0.002853069 | D22: 93117.48 | E22: =LN(D22)-LN(D21) -> 0.019639724
A23: 02/20/2025 | B23: 342 | C23: =LN(B23)-LN(B22) -> -0.023122417 | D23: 92958.43 | E23: =LN(D23)-LN(D22) -> -0.0017095178 | H23: Coefficients | I23: Standard Error | J23: t Stat | K23: P-value | L23: Lower 95% | M23: Upper 95% | N23: Lower 95,0% | O23: Upper 95,0%
A24: 02/19/2025 | B24: 347 | C24: =LN(B24)-LN(B23) -> 0.014514043 | D24: 93461.23 | E24: =LN(D24)-LN(D23) -> 0.0053942939 | G24: Intercept | H24: -0.0014710653 | I24: 0.00082043356 | J24: -1.793034 | K24: 0.073125159 | L24: -0.003080102 | M24: 0.00013797138 | N24: -0.003080102 | O24: 0.00013797138
A25: 02/18/2025 | B25: 352 | C25: =LN(B25)-LN(B24) -> 0.014306396 | D25: 94650.54 | E25: =LN(D25)-LN(D24) -> 0.012644885 | G25: X Variable 1 | H25: 0.44142382 | I25: 0.059304715 | J25: 7.4433174 | K25: 1.4752111e-13 | L25: 0.32511524 | M25: 0.55773239 | N25: 0.32511524 | O25: 0.55773239
A26: 02/17/2025 | B26: 353 | C26: =LN(B26)-LN(B25) -> 0.0028368813 | D26: 92461.23 | E26: =LN(D26)-LN(D25) -> -0.023402161
A27: 02/14/2025 | B27: 365.5 | C27: =LN(B27)-LN(B26) -> 0.034798222 | D27: 91788.05 | E27: =LN(D27)-LN(D26) -> -0.0073073067
A28: 02/13/2025 | B28: 365 | C28: =LN(B28)-LN(B27) -> -0.0013689256 | D28: 92342.43 | E28: =LN(D28)-LN(D27) -> 0.0060216177
A29: 02/12/2025 | B29: 366.5 | C29: =LN(B29)-LN(B28) -> 0.0041011677 | D29: 91778.14 | E29: =LN(D29)-LN(D28) -> -0.0061295896
A30: 02/11/2025 | B30: 365.5 | C30: =LN(B30)-LN(B29) -> -0.0027322421 | D30: 90993.39 | E30: =LN(D30)-LN(D29) -> -0.0085872764
A31: 02/10/2025 | B31: 369.5 | C31: =LN(B31)-LN(B30) -> 0.010884461 | D31: 89895.48 | E31: =LN(D31)-LN(D30) -> -0.012139204
A32: 02/07/2025 | B32: 366 | C32: =LN(B32)-LN(B31) -> -0.009517407 | D32: 89150.14 | E32: =LN(D32)-LN(D31) -> -0.0083257474
A33: 02/06/2025 | B33: 369 | C33: =LN(B33)-LN(B32) -> 0.0081633106 | D33: 88376.12 | E33: =LN(D33)-LN(D32) -> -0.0087201173
A34: 02/05/2025 | B34: 360 | C34: =LN(B34)-LN(B33) -> -0.024692613 | D34: 86131.83 | E34: =LN(D34)-LN(D33) -> -0.025722768
A35: 02/04/2025 | B35: 360 | C35: =LN(B35)-LN(B34) -> 0 | D35: 86793.21 | E35: =LN(D35)-LN(D34) -> 0.0076493633
A36: 02/03/2025 | B36: 358 | C36: =LN(B36)-LN(B35) -> -0.005571045 | D36: 85963.68 | E36: =LN(D36)-LN(D35) -> -0.0096035113
A37: 01/31/2025 | B37: 365 | C37: =LN(B37)-LN(B36) -> 0.019364367 | D37: 87367.57 | E37: =LN(D37)-LN(D36) -> 0.01619928
... A1921: 11/10/2014 | B1921: 14.9 | C1921: =LN(B1921)-LN(B1920) -> 0.011474982 | D1921: 53106.5 | E1921: =LN(D1921)-LN(D1920) -> 0.0017140646

Sheet Expected Return
B1: Warsaw Stock Exchange WIG, 20 years
B3: Date | C3: Closeprice
B4: 12/01/2024 | C4: 79577.32 | D4: =(C4/C15)-1 -> 0.027914144 | G4: 10 years average return: | H4: =AVERAGE(D:D) -> 0.040018884
B5: 11/01/2024 | C5: 79369.82
B6: 10/01/2024 | C6: 79550.32
B7: 09/01/2024 | C7: 83274.2 | O7: MSCI World 10 years average return: | P7: 0.104
B8: 08/01/2024 | C8: 84868.25 | G8: 10 years CAGR return: | H8: =(C4/C135)^(1/10)-1 -> 0.045840713
B9: 07/01/2024 | C9: 84345.7
B10: 06/01/2024 | C10: 88613.67 | N10: Source: | O10: https://www.msci.com/documents/10199/178e6643-6ae6-47b9-82be-e1fc565ededb
B11: 05/01/2024 | C11: 86315.26
B12: 04/01/2024 | C12: 84569.65 | G12: 20 years CAGR return: | H12: 0.0562 | J12: Source: | K12: https://www.gpw.pl/gpw-key-statistics
B13: 03/01/2024 | C13: 82745.58
B14: 02/01/2024 | C14: 81944.56
B15: 01/01/2024 | C15: 77416.31
B16: 12/01/2023 | C16: 78459.91 | D16: =(C16/C27)-1 -> 0.28021355
B17: 11/01/2023 | C17: 74264.07
B18: 10/01/2023 | C18: 71582.26
B19: 09/01/2023 | C19: 65397.43
B20: 08/01/2023 | C20: 68431.46
B21: 07/01/2023 | C21: 72268.53
B22: 06/01/2023 | C22: 67283.22
B23: 05/01/2023 | C23: 62285.97
B24: 04/01/2023 | C24: 62948.5
B25: 03/01/2023 | C25: 58608.76
B26: 02/01/2023 | C26: 60181.4
B27: 01/01/2023 | C27: 61286.58
B28: 12/01/2022 | C28: 57462.68 | D28: =(C28/C39)-1 -> -0.14767079
B29: 11/01/2022 | C29: 56058.18
B30: 10/01/2022 | C30: 50432.55
B31: 09/01/2022 | C31: 45970.64
B32: 08/01/2022 | C32: 50174.09
B33: 07/01/2022 | C33: 55007.36
B34: 06/01/2022 | C34: 53573.42
B35: 05/01/2022 | C35: 57432.29
B36: 04/01/2022 | C36: 57754.98
B37: 03/01/2022 | C37: 64900.36
B38: 02/01/2022 | C38: 61141.35
B39: 01/01/2022 | C39: 67418.41
B40: 12/01/2021 | C40: 69296.26 | D40: =(C40/C51)-1 -> 0.21617875
B41: 11/01/2021 | C41: 67814.89
...
